Workbook

Sheet Quarterly_Analysis
A1: QUARTERLY FINANCIAL ANALYSIS
A2: 2025 Performance Trends and Comparisons
A4: Quarter | B4: Q1 2025 | C4: Q2 2025 | D4: Q3 2025 | E4: Q4 2025 | F4: Total 2025 | G4: QoQ Growth | H4: YoY Growth
A5: Revenue Analysis
A6: Product Sales | B6: =Income_Statement!B6 -> 1250000 | C6: =Income_Statement!C6 -> 1350000 | D6: =Income_Statement!D6 -> 1420000 | E6: =Income_Statement!E6 -> 1580000 | F6: =SUM(B6:E6) -> 5600000
A7: Service Revenue | B7: =Income_Statement!B7 -> 450000 | C7: =Income_Statement!C7 -> 480000 | D7: =Income_Statement!D7 -> 520000 | E7: =Income_Statement!E7 -> 550000 | F7: =SUM(B7:E7) -> 2000000
A8: Subscription Fees | B8: =Income_Statement!B8 -> 320000 | C8: =Income_Statement!C8 -> 350000 | D8: =Income_Statement!D8 -> 380000 | E8: =Income_Statement!E8 -> 420000 | F8: =SUM(B8:E8) -> 1470000
A9: Other Income | B9: =Income_Statement!B9 -> 75000 | C9: =Income_Statement!C9 -> 82000 | D9: =Income_Statement!D9 -> 90000 | E9: =Income_Statement!E9 -> 95000 | F9: =SUM(B9:E9) -> 342000
A10: Total Revenue | B10: =Income_Statement!B10 -> 2095000 | C10: =Income_Statement!C10 -> 2262000 | D10: =Income_Statement!D10 -> 2410000 | E10: =Income_Statement!E10 -> 2645000 | F10: =SUM(B10:E10) -> 9412000
A11: Revenue Growth Rate | B11: =0 -> 0 | C11: =(C10-B10)/B10 -> 0.079713604 | D11: =(D10-C10)/C10 -> 0.065428824 | E11: =(E10-D10)/D10 -> 0.097510373 | F11: =(E10-B10)/B10 -> 0.26252983
A13: Profitability Analysis
A14: Gross Profit | B14: =Income_Statement!B18 -> 1045000 | C14: =Income_Statement!C18 -> 1162000 | D14: =Income_Statement!D18 -> 1260000 | E14: =Income_Statement!E18 -> 1430000 | F14: =SUM(B14:E14) -> 4897000
A15: Gross Margin % | B15: =B14/B10 -> 0.49880668 | C15: =C14/C10 -> 0.51370469 | D15: =D14/D10 -> 0.52282158 | E15: =E14/E10 -> 0.54064272 | F15: =F14/F10 -> 0.52029324
A16: Operating Income | B16: =Income_Statement!B29 -> 355000 | C16: =Income_Statement!C29 -> 438000 | D16: =Income_Statement!D29 -> 505000 | E16: =Income_Statement!E29 -> 638000 | F16: =SUM(B16:E16) -> 1936000
A17: Operating Margin % | B17: =B16/B10 -> 0.16945107 | C17: =C16/C10 -> 0.19363395 | D17: =D16/D10 -> 0.20954357 | E17: =E16/E10 -> 0.24120983 | F17: =F16/F10 -> 0.20569486
A18: Net Income | B18: =Income_Statement!B41 -> 276500 | C18: =Income_Statement!C41 -> 344440 | D18: =Income_Statement!D41 -> 398950 | E18: =Income_Statement!E41 -> 505600 | F18: =SUM(B18:E18) -> 1525490
A19: Net Margin % | B19: =B18/B10 -> 0.13198091 | C19: =C18/C10 -> 0.15227233 | D19: =D18/D10 -> 0.16553942 | E19: =E18/E10 -> 0.19115312 | F19: =F18/F10 -> 0.16207926
A21: Expense Analysis
A22: COGS | B22: =Income_Statement!B16 -> 1050000 | C22: =Income_Statement!C16 -> 1100000 | D22: =Income_Statement!D16 -> 1150000 | E22: =Income_Statement!E16 -> 1215000 | F22: =SUM(B22:E22) -> 4515000
A23: COGS % of Revenue | B23: =B22/B10 -> 0.50119332 | C23: =C22/C10 -> 0.48629531 | D23: =D22/D10 -> 0.47717842 | E23: =E22/E10 -> 0.45935728 | F23: =F22/F10 -> 0.47970676
A24: Operating Expenses | B24: =Income_Statement!B27 -> 690000 | C24: =Income_Statement!C27 -> 724000 | D24: =Income_Statement!D27 -> 755000 | E24: =Income_Statement!E27 -> 792000 | F24: =SUM(B24:E24) -> 2961000
A25: OpEx % of Revenue | B25: =B24/B10 -> 0.32935561 | C25: =C24/C10 -> 0.32007073 | D25: =D24/D10 -> 0.31327801 | E25: =E24/E10 -> 0.29943289 | F25: =F24/F10 -> 0.31459839
A26: Marketing Expenses | B26: =Income_Statement!B21 -> 85000 | C26: =Income_Statement!C21 -> 92000 | D26: =Income_Statement!D21 -> 98000 | E26: =Income_Statement!E21 -> 105000 | F26: =SUM(B26:E26) -> 380000
A27: R&D Expenses | B27: =Income_Statement!B22 -> 120000 | C27: =Income_Statement!C22 -> 125000 | D27: =Income_Statement!D22 -> 130000 | E27: =Income_Statement!E22 -> 135000 | F27: =SUM(B27:E27) -> 510000
A29: Key Metrics
A30: Earnings Per Share (EPS) | B30: =B18/125000 -> 2.212 | C30: =C18/125000 -> 2.75552 | D30: =D18/125000 -> 3.1916 | E30: =E18/125000 -> 4.0448 | F30: =F18/500000 -> 3.05098
A31: Operating Cash Flow | B31: =B18*0.8 -> 221200 | C31: =C18*0.8 -> 275552 | D31: =D18*0.8 -> 319160 | E31: =E18*0.8 -> 404480 | F31: =F18*0.8 -> 1220392
A32: Free Cash Flow | B32: =B31-50000 -> 171200 | C32: =C31-55000 -> 220552 | D32: =D31-60000 -> 259160 | E32: =E31-65000 -> 339480 | F32: =F31-230000 -> 990392
A33: Working Capital | B33: =Balance_Sheet!B11-Balance_Sheet!B32 -> 1600000 | C33: =B33*1.05 -> 1680000 | D33: =C33*1.03 -> 1730400 | E33: =D33*1.02 -> 1765008 | F33: =E33 -> 1765008
A34: Current Ratio | B34: =Balance_Sheet!B11/Balance_Sheet!B32 -> 2.1851852 | C34: =B34*1.02 -> 2.2288889 | D34: =C34*1.01 -> 2.2511778 | E34: =D34*1.01 -> 2.2736896 | F34: =E34 -> 2.2736896
A36: Quarterly Highlights
A37: Highest Revenue Quarter | B37: =INDEX(B4:E4,MATCH(MAX(B10:E10),B10:E10,0)) -> Q4 2025
A38: Highest Profit Quarter | B38: =INDEX(B4:E4,MATCH(MAX(B18:E18),B18:E18,0)) -> Q4 2025
A39: Most Efficient Quarter | B39: =INDEX(B4:E4,MATCH(MAX(B15:E15),B15:E15,0)) -> Q4 2025
A40: Strongest Growth Quarter | B40: =INDEX(B4:E4,MATCH(MAX(B11:E11),B11:E11,0)) -> Q4 2025

Sheet Financial_Ratios
A1: FINANCIAL RATIOS ANALYSIS
A2: Comprehensive Performance Metrics for 2025
A4: Ratio Category | B4: Ratio Name | C4: Formula | D4: 2025 Value | E4: Industry Avg | F4: Assessment
A5: Liquidity Ratios | B5: Current Ratio | C5: Current Assets / Current Liabilities | D5: =Balance_Sheet!B11/Balance_Sheet!B32 -> 2.1851852 | E5: 2 | F5: =IF(D5>=E5,"Strong","Weak") -> Strong
B6: Quick Ratio (Acid-Test) | C6: (Current Assets - Inventory) / Current Liabilities | D6: =(Balance_Sheet!B11-Balance_Sheet!B8)/Balance_Sheet!B32 -> 1.7037037 | E6: 1.5 | F6: =IF(D6>=E6,"Good","Poor") -> Good
B7: Cash Ratio | C7: Cash & Equivalents / Current Liabilities | D7: =Balance_Sheet!B6/Balance_Sheet!B32 -> 0.92592593 | E7: 0.4 | F7: =IF(D7>=E7,"Excellent","Adequate") -> Excellent
A8: Profitability Ratios | B8: Gross Profit Margin | C8: Gross Profit / Revenue | D8: =Income_Statement!F18/Income_Statement!F10 -> 0.52029324 | E8: 0.4 | F8: =IF(D8>=E8,"Good","Needs Improvement") -> Good
B9: Operating Margin | C9: Operating Income / Revenue | D9: =Income_Statement!F29/Income_Statement!F10 -> 0.20569486 | E9: 0.25 | F9: =IF(D9>=E9,"Good","Needs Improvement") -> Needs Improvement
B10: Net Profit Margin | C10: Net Income / Revenue | D10: =Income_Statement!F41/Income_Statement!F10 -> 0.17097641 | E10: 0.18 | F10: =IF(D10>=E10,"Good","Needs Improvement") -> Needs Improvement
B11: Return on Assets (ROA) | C11: Net Income / Total Assets | D11: =Income_Statement!F41/Balance_Sheet!B23 -> 0.18711977 | E11: 0.1 | F11: =IF(D11>=E11,"Good","Poor") -> Good
B12: Return on Equity (ROE) | C12: Net Income / Shareholders' Equity | D12: =Income_Statement!F41/Balance_Sheet!B49 -> 0.36993793 | E12: 0.18 | F12: =IF(D12>=E12,"Excellent","Good") -> Excellent
A13: Leverage Ratios | B13: Debt to Equity Ratio | C13: Total Debt / Total Equity | D13: =Balance_Sheet!B41/Balance_Sheet!B49 -> 0.97701149 | E13: 0.75 | F13: =IF(D13<=E13,"Good","High") -> High
B14: Debt Ratio | C14: Total Debt / Total Assets | D14: =Balance_Sheet!B41/Balance_Sheet!B23 -> 0.49418605 | E14: 0.55 | F14: =IF(D14<=E14,"Good","High") -> Good
B15: Interest Coverage Ratio | C15: EBIT / Interest Expense | D15: =Income_Statement!F29/Income_Statement!F33 -> 18.264151 | E15: 5 | F15: =IF(D15>=E15,"Strong","Weak") -> Strong
A16: Efficiency Ratios | B16: Asset Turnover Ratio | C16: Revenue / Total Assets | D16: =Income_Statement!F10/Balance_Sheet!B23 -> 1.0944186 | E16: 0.65 | F16: =IF(D16>=E16,"Good","Poor") -> Good
B17: Receivables Turnover | C17: Revenue / Average Receivables | D17: =Income_Statement!F10/((Balance_Sheet!B7+Balance_Sheet!C7)/2) -> 11.548466 | E17: 8 | F17: =IF(D17>=E17,"Good","Slow") -> Good
B18: Receivables Turnover | C18: Revenue / Average Receivables | D18: =Income_Statement!F10/((Balance_Sheet!B7+Balance_Sheet!C7)/2) -> 11.548466 | E18: 8 | F18: =IF(D18>=E18,"Good","Slow") -> Good
B19: Days Sales Outstanding (DSO) | C19: 365 / Receivables Turnover | D19: =365/D18 -> 31.605929 | E19: 45 | F19: =IF(D19<=E19,"Good","Slow") -> Good
A20: Market Ratios | B20: Price to Earnings (P/E) | C20: Market Price per Share / EPS | D20: 22.5 | E20: 20 | F20: =IF(D20<=E20,"Undervalued",IF(D20<=E20*1.2,"Fair","Overvalued")) -> Fair
B21: Earnings Per Share (EPS) | C21: Net Income / Shares Outstanding | D21: =Income_Statement!F41/500000 -> 3.21846 | E21: 3 | F21: =IF(D21>=E21,"Good","Below Target") -> Good
B22: Dividend Yield | C22: Dividends per Share / Price per Share | D22: 0.024 | E22: 0.025 | F22: =IF(D22>=E22,"Good","Below Avg") -> Below Avg
B23: Dividend Payout Ratio | C23: Dividends per Share / EPS | D23: 0.35 | E23: 0.4 | F23: =IF(D23<=E23,"Sustainable","High") -> Sustainable

Sheet Cash_Flow
A1: STATEMENT OF CASH FLOWS
A2: For the Year Ended December 31, 2025
A4: CASH FLOWS FROM OPERATING ACTIVITIES | B4: 2025 | C4: 2024
A5: Net Income | B5: =Income_Statement!F41 -> 1609230 | C5: 850000
A6: Adjustments to reconcile net income to net cash:
A7: Depreciation & Amortization | B7: 186000 | C7: 165000
A8: Deferred Income Taxes | B8: 45000 | C8: 40000
A9: Stock-based Compensation | B9: 32000 | C9: 28000
A10: Changes in Operating Assets & Liabilities:
A11: Accounts Receivable | B11: -70000 | C11: -60000
A12: Inventory | B12: -50000 | C12: -45000
A13: Prepaid Expenses | B13: -20000 | C13: -15000
A14: Accounts Payable | B14: 30000 | C14: 25000
A15: Accrued Expenses | B15: 30000 | C15: 25000
A16: Deferred Revenue | B16: 30000 | C16: 25000
A17: Other Operating Activities | B17: 15000 | C17: 10000
A18: Net Cash Provided by Operating Activities | B18: =SUM(B5:B17) -> 1837230 | C18: =SUM(C5:C17) -> 1048000
A20: CASH FLOWS FROM INVESTING ACTIVITIES
A21: Capital Expenditures | B21: -350000 | C21: -300000
A22: Purchase of Investments | B22: -200000 | C22: -150000
A23: Sale of Investments | B23: 120000 | C23: 100000
A24: Acquisition of Business | B24: -50000 | C24: -40000
A25: Proceeds from Sale of Assets | B25: 80000 | C25: 60000
A26: Other Investing Activities | B26: -20000 | C26: -15000
A27: Net Cash Used in Investing Activities | B27: =SUM(B21:B26) -> -420000 | C27: =SUM(C21:C26) -> -345000
A29: CASH FLOWS FROM FINANCING ACTIVITIES
A30: Proceeds from Issuance of Debt | B30: 250000 | C30: 200000
A31: Repayment of Debt | B31: -180000 | C31: -150000
A32: Proceeds from Issuance of Stock | B32: 100000 | C32: 80000
A33: Repurchase of Stock | B33: -20000 | C33: -15000
A34: Dividends Paid | B34: -120000 | C34: -100000
A35: Other Financing Activities | B35: -30000 | C35: -25000
A36: Net Cash Provided by (Used in) Financing Activities | B36: =SUM(B30:B35) -> 0 | C36: =SUM(C30:C35) -> -10000
A38: NET INCREASE (DECREASE) IN CASH | B38: =B18+B27+B36 -> 1417230 | C38: =C18+C27+C36 -> 693000
A39: Cash at Beginning of Period | B39: =Balance_Sheet!C6 -> 1100000 | C39: 950000
A40: Cash at End of Period | B40: =B39+B38 -> 2517230 | C40: =C39+C38 -> 1643000

Sheet Balance_Sheet
A1: COMPANY BALANCE SHEET
A2: As of December 31, 2025
A4: ASSETS | B4: 2025 | C4: 2024 | D4: Change
A5: Current Assets
A6: Cash and Cash Equivalents | B6: 1250000 | C6: 1100000 | D6: =B6-C6 -> 150000
A7: Accounts Receivable | B7: 850000 | C7: 780000 | D7: =B7-C7 -> 70000
A8: Inventory | B8: 650000 | C8: 600000 | D8: =B8-C8 -> 50000
A9: Prepaid Expenses | B9: 120000 | C9: 100000 | D9: =B9-C9 -> 20000
A10: Other Current Assets | B10: 80000 | C10: 70000 | D10: =B10-C10 -> 10000
A11: Total Current Assets | B11: =SUM(B6:B10) -> 2950000 | C11: =SUM(C6:C10) -> 2650000 | D11: =B11-C11 -> 300000
A13: Non-Current Assets
A14: Property, Plant & Equipment | B14: 4200000 | C14: 3800000 | D14: =B14-C14 -> 400000
A15: Less: Accumulated Depreciation | B15: 1250000 | C15: 1100000 | D15: =B15-C15 -> 150000
A16: Net Property, Plant & Equipment | B16: =B14-B15 -> 2950000 | C16: =C14-C15 -> 2700000 | D16: =B16-C16 -> 250000
A17: Intangible Assets | B17: 850000 | C17: 800000 | D17: =B17-C17 -> 50000
A18: Goodwill | B18: 1200000 | C18: 1150000 | D18: =B18-C18 -> 50000
A19: Long-term Investments | B19: 500000 | C19: 450000 | D19: =B19-C19 -> 50000
A20: Other Non-Current Assets | B20: 150000 | C20: 120000 | D20: =B20-C20 -> 30000
A21: Total Non-Current Assets | B21: =SUM(B16:B20) -> 5650000 | C21: =SUM(C16:C20) -> 5220000 | D21: =B21-C21 -> 430000
A23: TOTAL ASSETS | B23: =B11+B21 -> 8600000 | C23: =C11+C21 -> 7870000 | D23: =B23-C23 -> 730000
A25: LIABILITIES & EQUITY
A26: Current Liabilities
A27: Accounts Payable | B27: 450000 | C27: 420000 | D27: =B27-C27 -> 30000
A28: Short-term Debt | B28: 350000 | C28: 300000 | D28: =B28-C28 -> 50000
A29: Accrued Expenses | B29: 280000 | C29: 250000 | D29: =B29-C29 -> 30000
A30: Deferred Revenue | B30: 150000 | C30: 120000 | D30: =B30-C30 -> 30000
A31: Other Current Liabilities | B31: 120000 | C31: 100000 | D31: =B31-C31 -> 20000
A32: Total Current Liabilities | B32: =SUM(B27:B31) -> 1350000 | C32: =SUM(C27:C31) -> 1190000 | D32: =B32-C32 -> 160000
A34: Non-Current Liabilities
A35: Long-term Debt | B35: 2200000 | C35: 2000000 | D35: =B35-C35 -> 200000
A36: Deferred Tax Liabilities | B36: 350000 | C36: 300000 | D36: =B36-C36 -> 50000
A37: Pension Obligations | B37: 250000 | C37: 200000 | D37: =B37-C37 -> 50000
A38: Other Long-term Liabilities | B38: 100000 | C38: 80000 | D38: =B38-C38 -> 20000
A39: Total Non-Current Liabilities | B39: =SUM(B35:B38) -> 2900000 | C39: =SUM(C35:C38) -> 2580000 | D39: =B39-C39 -> 320000
A41: TOTAL LIABILITIES | B41: =B32+B39 -> 4250000 | C41: =C32+C39 -> 3770000 | D41: =B41-C41 -> 480000
A43: SHAREHOLDERS' EQUITY
A44: Common Stock | B44: 1000000 | C44: 1000000 | D44: =B44-C44 -> 0
A45: Additional Paid-in Capital | B45: 1500000 | C45: 1500000 | D45: =B45-C45 -> 0
A46: Retained Earnings | B46: 1800000 | C46: 1500000 | D46: =B46-C46 -> 300000
A47: Treasury Stock | B47: -50000 | C47: -30000 | D47: =B47-C47 -> -20000
...

Sheet Income_Statement
A1: COMPANY FINANCIAL REPORT - INCOME STATEMENT
A2: Fiscal Year 2025
A4: Category | B4: Q1 2025 | C4: Q2 2025 | D4: Q3 2025 | E4: Q4 2025 | F4: Total 2025
A5: REVENUE
A6: Product Sales | B6: 1250000 | C6: 1350000 | D6: 1420000 | E6: 1580000 | F6: =SUM(B6:E6) -> 5600000
A7: Service Revenue | B7: 450000 | C7: 480000 | D7: 520000 | E7: 550000 | F7: =SUM(B7:E7) -> 2000000
A8: Subscription Fees | B8: 320000 | C8: 350000 | D8: 380000 | E8: 420000 | F8: =SUM(B8:E8) -> 1470000
A9: Other Income | B9: 75000 | C9: 82000 | D9: 90000 | E9: 95000 | F9: =SUM(B9:E9) -> 342000
A10: Total Revenue | B10: =SUM(B6:B9) -> 2095000 | C10: =SUM(C6:C9) -> 2262000 | D10: =SUM(D6:D9) -> 2410000 | E10: =SUM(E6:E9) -> 2645000 | F10: =SUM(F6:F9) -> 9412000
A12: COST OF GOODS SOLD
A13: Direct Materials | B13: 650000 | C13: 680000 | D13: 710000 | E13: 750000 | F13: =SUM(B13:E13) -> 2790000
A14: Direct Labor | B14: 280000 | C14: 295000 | D14: 310000 | E14: 330000 | F14: =SUM(B14:E14) -> 1215000
A15: Manufacturing Overhead | B15: 120000 | C15: 125000 | D15: 130000 | E15: 135000 | F15: =SUM(B15:E15) -> 510000
A16: Total COGS | B16: =SUM(B13:B15) -> 1050000 | C16: =SUM(C13:C15) -> 1100000 | D16: =SUM(D13:D15) -> 1150000 | E16: =SUM(E13:E15) -> 1215000 | F16: =SUM(F13:F15) -> 4515000
A18: GROSS PROFIT | B18: =B10-B16 -> 1045000 | C18: =C10-C16 -> 1162000 | D18: =D10-D16 -> 1260000 | E18: =E10-E16 -> 1430000 | F18: =F10-F16 -> 4897000
A20: OPERATING EXPENSES
A21: Marketing & Advertising | B21: 85000 | C21: 92000 | D21: 98000 | E21: 105000 | F21: =SUM(B21:E21) -> 380000
A22: Research & Development | B22: 120000 | C22: 125000 | D22: 130000 | E22: 135000 | F22: =SUM(B22:E22) -> 510000
A23: Salaries & Benefits | B23: 350000 | C23: 365000 | D23: 380000 | E23: 400000 | F23: =SUM(B23:E23) -> 1495000
A24: Rent & Utilities | B24: 65000 | C24: 68000 | D24: 70000 | E24: 72000 | F24: =SUM(B24:E24) -> 275000
A25: Depreciation | B25: 45000 | C25: 46000 | D25: 47000 | E25: 48000 | F25: =SUM(B25:E25) -> 186000
A26: Other Operating Expenses | B26: 25000 | C26: 28000 | D26: 30000 | E26: 32000 | F26: =SUM(B26:E26) -> 115000
A27: Total Operating Expenses | B27: =SUM(B21:B26) -> 690000 | C27: =SUM(C21:C26) -> 724000 | D27: =SUM(D21:D26) -> 755000 | E27: =SUM(E21:E26) -> 792000 | F27: =SUM(F21:F26) -> 2961000
A29: OPERATING INCOME | B29: =B18-B27 -> 355000 | C29: =C18-C27 -> 438000 | D29: =D18-D27 -> 505000 | E29: =E18-E27 -> 638000 | F29: =F18-F27 -> 1936000
A31: NON-OPERATING ITEMS
A32: Interest Income | B32: 15000 | C32: 18000 | D32: 20000 | E32: 22000 | F32: =SUM(B32:E32) -> 75000
A33: Interest Expense | B33: 25000 | C33: 26000 | D33: 27000 | E33: 28000 | F33: =SUM(B33:E33) -> 106000
A34: Other Non-Operating | B34: 5000 | C34: 6000 | D34: 7000 | E34: 8000 | F34: =SUM(B34:E34) -> 26000
A35: Total Non-Operating | B35: =B32-B33+B34 -> -5000 | C35: =C32-C33+C34 -> -2000 | D35: =D32-D33+D34 -> 0 | E35: =E32-E33+E34 -> 2000 | F35: =SUM(F32:F34)-F33 -> 101000
A37: PRE-TAX INCOME | B37: =B29+B35 -> 350000 | C37: =C29+C35 -> 436000 | D37: =D29+D35 -> 505000 | E37: =E29+E35 -> 640000 | F37: =F29+F35 -> 2037000
A39: Income Tax Expense | B39: =B37*0.21 -> 73500 | C39: =C37*0.21 -> 91560 | D39: =D37*0.21 -> 106050 | E39: =E37*0.21 -> 134400 | F39: =F37*0.21 -> 427770
A41: NET INCOME | B41: =B37-B39 -> 276500 | C41: =C37-C39 -> 344440 | D41: =D37-D39 -> 398950 | E41: =E37-E39 -> 505600 | F41: =F37-F39 -> 1609230

Sheet Dashboard
A1: COMPANY FINANCIAL DASHBOARD
A2: Real-Time Financial Performance Overview
A4: KEY PERFORMANCE INDICATORS
A5: Metric | B5: Value | C5: Target | D5: Status | E5: Trend
A6: Total Revenue | B6: =Income_Statement!F10 -> 9412000 | C6: 6000000 | D6: =IF(B6>=C6,"On Target","Below Target") -> On Target | E6: =IF(B6>Income_Statement!E10,"↑",IF(B6<Income_Statement!E10,"↓","→")) -> ↑
A7: Gross Profit Margin | B7: =Income_Statement!F18/Income_Statement!F10 -> 0.52029324 | C7: 0.45 | D7: =IF(B7>=C7,"On Target","Below Target") -> On Target | E7: =IF(B7>Income_Statement!E18/Income_Statement!E10,"↑",IF(B7<Income_Statement!E18/Income_Statement!E10,"↓","→")) -> ↓
A8: Operating Margin | B8: =Income_Statement!F29/Income_Statement!F10 -> 0.20569486 | C8: 0.25 | D8: =IF(B8>=C8,"On Target","Below Target") -> Below Target | E8: =IF(B8>Income_Statement!E29/Income_Statement!E10,"↑",IF(B8<Income_Statement!E29/Income_Statement!E10,"↓","→")) -> ↓
A9: Net Profit Margin | B9: =Income_Statement!F41/Income_Statement!F10 -> 0.17097641 | C9: 0.18 | D9: =IF(B9>=C9,"On Target","Below Target") -> Below Target | E9: =IF(B9>Income_Statement!E41/Income_Statement!E10,"↑",IF(B9<Income_Statement!E41/Income_Statement!E10,"↓","→")) -> ↓
A10: Current Ratio | B10: 2.5 | C10: 2 | D10: =IF(B10>=C10,"Strong","Weak") -> Strong | E10: →
A11: Debt to Equity Ratio | B11: 0.65 | C11: 0.75 | D11: =IF(B11<=C11,"Good","High") -> Good | E11: →
A12: Return on Assets (ROA) | B12: 0.12 | C12: 0.1 | D12: =IF(B12>=C12,"Good","Poor") -> Good | E12: ↑
A13: Return on Equity (ROE) | B13: 0.22 | C13: 0.18 | D13: =IF(B13>=C13,"Excellent","Good") -> Excellent | E13: ↑
A14: Earnings Per Share (EPS) | B14: 3.45 | C14: 3 | D14: =IF(B14>=C14,"Above Target","Below Target") -> Above Target | E14: ↑
A15: Quarterly Growth Rate | B15: 0.085 | C15: 0.1 | D15: =IF(B15>=C15,"On Track","Needs Improvement") -> Needs Improvement | E15: →
A17: FINANCIAL HIGHLIGHTS
A18: Total Assets | B18: 8500000
A19: Total Liabilities | B19: 4200000
A20: Shareholder Equity | B20: 4300000
A21: Cash & Equivalents | B21: 1250000
A22: Working Capital | B22: 2100000
A24: PERFORMANCE TRENDS
A25: Revenue Growth (YoY) | B25: 0.15
A26: Profit Growth (YoY) | B26: 0.22
A27: Expense Ratio | B27: 0.68
A29: UPCOMING MILESTONES
A30: Q1 2026 Revenue Target | B30: 1650000
A31: Q1 2026 Profit Target | B31: 450000
A32: Annual Growth Target | B32: 0.2
A35: Report Generated: January 2026
A36: =HYPERLINK("https://mica.mindlink.tools", "Copyright © 2025 MICA") -> Copyright © 2025 MICA
